Workbook

Sheet README
A1: Rolodex price data
A2: New-home prices by builder in Greater Houston and Dallas-Fort Worth masterplanned communities. Read 2026-09-27. Prepared by Héctor Ibarzábal.
A4: Tables
A5: Sheet | B5: Rows | C5: What it holds
A6: Homes | B6: =COUNTA('Homes'!A:A)-1 | C6: One row per move-in-ready home: list price, size, rooms, garage, stories, status, lot width, builder, community, location, ZIP resale. The table for a hedonic model.
A7: ProductLines | B7: =COUNTA('ProductLines'!A:A)-1 | C7: One row per builder product line in a community: starting price, lot widths, size range, incentive text. The unit the builder prices.
A8: Communities | B8: =COUNTA('Communities'!A:A)-1 | C8: One row per masterplanned community, with its ZIP resale figures and a computed distance to downtown.
A9: Builders | B9: =COUNTA('Builders'!A:A)-1 | C9: One row per builder per market, with the Rolodex counts and published closings.
A10: Developers | B10: =COUNTA('Developers'!A:A)-1 | C10: One row per land developer per market.
A11: CommunityFacts | B11: =COUNTA('CommunityFacts'!A:A)-1 | C11: Sourced facts about each community, one per row (qualitative).
A12: Text | B12: =COUNTA('Text'!A:A)-1 | C12: Every free-text field in long form for text analysis: facts, incentives, price wording, land-record source lines.
A13: Land | B13: =COUNTA('Land'!A:A)-1 | C13: Land and lot records: Howard Hughes price an acre, lot prices, lot supply. Source text kept.
A14: Filings | B14: =COUNTA('Filings'!A:A)-1 | C14: Figures read from public builders' SEC filings, with the source line.
A15: ZIPs | B15: =COUNTA('ZIPs'!A:A)-1 | C15: Latest Zillow and Redfin figures for each ZIP with a community in it.
A16: ZIP_ZHVI_Monthly | B16: =COUNTA('ZIP_ZHVI_Monthly'!A:A)-1 | C16: Zillow home value index by ZIP and month (long).
A17: ZIP_Redfin_Quarterly | B17: =COUNTA('ZIP_Redfin_Quarterly'!A:A)-1 | C17: Redfin median sale price and price a sq ft by ZIP and quarter (long).
A18: Metro_Monthly | B18: =COUNTA('Metro_Monthly'!A:A)-1 | C18: Zillow metro series by month (long): zhvi_sfr, newcon_price, newcon_ppsf, newcon_sales, sales_all, median_sale_sfr, inventory.
A19: Permits | B19: =COUNTA('Permits'!A:A)-1 | C19: Census Building Permits Survey, single-family, by county and year.
A20: Model_Summary | B20: =COUNTA('Model_Summary'!A:A)-1 | C20: Baseline hedonic regressions of log list price (fit here in Python; see Model_Terms).
A21: Model_Terms | B21: =COUNTA('Model_Terms'!A:A)-1 | C21: Coefficients of the baseline models, standard errors clustered by community. Community and builder fixed effects not listed.
A22: Community_Premium | B22: =COUNTA('Community_Premium'!A:A)-1 | C22: Model P community effects: what a home of the same floor area lists for in each community, against the market's median community.
A24: How it was read
A25: Prices are list prices on each builder or community page, found again on the page by a script before they were kept. No listing portal is a source. List prices are not sale prices.
A26: Room counts, garage, stories, address and status were read from the same pages: the listing card that carries the home's price and floor area. A field the card does not print is blank; nothing is imputed.
A27: Lot width is known for a home only when its product line offers one width. Location is the community's point: where the Census geocoder places its homes, or its ZIP center. Not the lot.
A28: Up to five move-in-ready homes were read a product line, so a line with many homes on sale counts no more than one with five. qmi_listed in ProductLines gives how many each line listed.
A29: Every home was read again on its page the day it was read; a home no longer on its page was dropped. Perry Homes homes carry the address, rooms and status from Perry's own section pages.
A30: Rows flagged possible_duplicate repeat a home earlier in the table. The models keep the first copy.
A32: For a hedonic model
A33: Homes is the frame: log list_price on log sqft, beds, baths_total, garage_spaces, stories, lot_width_ft, status, with community and builder fixed effects. Model_Summary gives a baseline fit.
A34: Missing here, and worth adding: lot area, MUD or PID tax rate and HOA dues (large in Texas), exact lot coordinates, finish level, and sale prices with dates for a time index.
A35: Selection: move-in-ready inventory is what was unsold on the day read. It may differ from the homes that sold.
A37: Sources: builder and community pages (linked per row), Zillow Research, Redfin Data Center, US Census Building Permits Survey, SEC EDGAR, RCLCO, and published reports linked in Land.
... A40: Every column is described in the Dictionary sheet, the last tab.

Sheet Homes
A1: home_id | B1: market | C1: community_id | D1: community | E1: county | F1: city | G1: zip | H1: developer | I1: school_district | J1: builder | K1: builder_id | L1: rolodex_section | M1: rolodex_repetition | N1: rolodex_printer_fit | O1: rolodex_track_record | P1: builder_sec_filer | Q1: line_id | R1: product_line | S1: lot_width_ft | T1: lot_widths_offered_ft | U1: plan | V1: list_price | W1: sqft | X1: price_per_sqft | Y1: beds | Z1: full_baths | AA1: half_baths | AB1: baths_total | AC1: garage_spaces | AD1: stories | AE1: status | AF1: status_text | AG1: was_price | AH1: cut_from_was | AI1: savings_stated | AJ1: line_incentive_text | AK1: address | AL1: miles_to_nearest_cbd | AM1: nearest_cbd | AN1: zip_zhvi | AO1: zip_zhvi_yoy | AP1: zip_redfin_median_sale | AQ1: zip_redfin_ppsf | AR1: community_acres | AS1: community_rclco_rank | AT1: possible_duplicate | AU1: listing_url | AV1: attributes_read_from | AW1: home_key | AX1: read_on
A2: 1 | B2: houston | C2: hou-artavia | D2: ARTAVIA | E2: Montgomery | F2: Conroe | G2: 77302 | H2: AIRIA Development Company | I2: Conroe ISD | J2: Beazer Homes | K2: b-houston-beazer-homes | L2: National builder | M2: Yes | N2: No | O2: No | P2: Beazer Homes | Q2: hou-artavia#1 | S2: 65 | T2: 65 | U2: Fredericksburg | V2: 499567 | W2: 2948 | X2: =IF(W2>0,V2/W2,"") | Y2: 4 | Z2: 3 | AA2: 1 | AB2: =IF(Z2="","",Z2+0.5*N(AA2)) | AE2: ready | AF2: Available Now | AH2: =IF(AG2="","",1-V2/AG2) | AJ2: For a limited time, receive 50% off options up to $100,000 for your new to-be-built home when you use a Choice Lender!* | AK2: 17016 Sweet Iris Court | AL2: 30.7 | AM2: Houston | AN2: 326778 | AO2: -0.0227 | AP2: 335775 | AQ2: 153 | AR2: 2842 | AU2: https://www.beazer.com/houston-TX/conroe/artavia | AV2: https://www.beazer.com/houston-TX/conroe/artavia | AW2: hcb2de693b | AX2: 2026-09-27
A3: 2 | B3: houston | C3: hou-artavia | D3: ARTAVIA | E3: Montgomery | F3: Conroe | G3: 77302 | H3: AIRIA Development Company | I3: Conroe ISD | J3: Beazer Homes | K3: b-houston-beazer-homes | L3: National builder | M3: Yes | N3: No | O3: No | P3: Beazer Homes | Q3: hou-artavia#1 | S3: 65 | T3: 65 | U3: Harper | V3: 499987 | W3: 3639 | X3: =IF(W3>0,V3/W3,"") | Y3: 4 | Z3: 3 | AA3: 1 | AB3: =IF(Z3="","",Z3+0.5*N(AA3)) | AE3: ready | AF3: Available Now | AH3: =IF(AG3="","",1-V3/AG3) | AJ3: For a limited time, receive 50% off options up to $100,000 for your new to-be-built home when you use a Choice Lender!* | AK3: 17315 July Moon Lane | AL3: 30.7 | AM3: Houston | AN3: 326778 | AO3: -0.0227 | AP3: 335775 | AQ3: 153 | AR3: 2842 | AU3: https://www.beazer.com/houston-TX/conroe/artavia | AV3: https://www.beazer.com/houston-TX/conroe/artavia | AW3: h0d9de8ea7 | AX3: 2026-09-27
A4: 3 | B4: houston | C4: hou-artavia | D4: ARTAVIA | E4: Montgomery | F4: Conroe | G4: 77302 | H4: AIRIA Development Company | I4: Conroe ISD | J4: Beazer Homes | K4: b-houston-beazer-homes | L4: National builder | M4: Yes | N4: No | O4: No | P4: Beazer Homes | Q4: hou-artavia#1 | S4: 65 | T4: 65 | U4: Northcliffe | V4: 568701 | W4: 3908 | X4: =IF(W4>0,V4/W4,"") | Y4: 5 | Z4: 4 | AA4: 1 | AB4: =IF(Z4="","",Z4+0.5*N(AA4)) | AE4: ready | AF4: Available Now | AH4: =IF(AG4="","",1-V4/AG4) | AJ4: For a limited time, receive 50% off options up to $100,000 for your new to-be-built home when you use a Choice Lender!* | AK4: 17211 Begonia Bend Dr | AL4: 30.7 | AM4: Houston | AN4: 326778 | AO4: -0.0227 | AP4: 335775 | AQ4: 153 | AR4: 2842 | AU4: https://www.beazer.com/houston-TX/conroe/artavia | AV4: https://www.beazer.com/houston-TX/conroe/artavia | AW4: h97ec9879a | AX4: 2026-09-27
A5: 4 | B5: houston | C5: hou-artavia | D5: ARTAVIA | E5: Montgomery | F5: Conroe | G5: 77302 | H5: AIRIA Development Company | I5: Conroe ISD | J5: David Weekley Homes | K5: b-houston-david-weekley-homes | L5: National builder | M5: Yes | N5: No | O5: No | Q5: hou-artavia#3 | R5: Reserve Collection | S5: 45 | T5: 45 | U5: Plan A297 | V5: 449990 | W5: 2600 | X5: =IF(W5>0,V5/W5,"") | Y5: 4 | Z5: 3 | AA5: 1 | AB5: =IF(Z5="","",Z5+0.5*N(AA5)) | AC5: 2 | AD5: 2 | AE5: ready | AF5: Ready Now | AH5: =IF(AG5="","",1-V5/AG5) | AK5: 15231 Osie Limestone Lane | AL5: 30.7 | AM5: Houston | AN5: 326778 | AO5: -0.0227 | AP5: 335775 | AQ5: 153 | AR5: 2842 | AU5: https://www.davidweekleyhomes.com/new-homes/tx/houston/conroe/artavia-45-homesites | AV5: https://www.davidweekleyhomes.com/new-homes/tx/houston/conroe/artavia-45-homesites | AW5: h0b42d27d6 | AX5: 2026-09-27
A6: 5 | B6: houston | C6: hou-artavia | D6: ARTAVIA | E6: Montgomery | F6: Conroe | G6: 77302 | H6: AIRIA Development Company | I6: Conroe ISD | J6: David Weekley Homes | K6: b-houston-david-weekley-homes | L6: National builder | M6: Yes | N6: No | O6: No | Q6: hou-artavia#3 | R6: Reserve Collection | S6: 45 | T6: 45 | U6: Plan B257 | V6: 425990 | W6: 2288 | X6: =IF(W6>0,V6/W6,"") | Y6: 4 | Z6: 3 | AA6: 1 | AB6: =IF(Z6="","",Z6+0.5*N(AA6)) | AC6: 2 | AD6: 1 | AH6: =IF(AG6="","",1-V6/AG6) | AK6: 15110 London Gavroche Lane | AL6: 30.7 | AM6: Houston | AN6: 326778 | AO6: -0.0227 | AP6: 335775 | AQ6: 153 | AR6: 2842 | AU6: https://www.davidweekleyhomes.com/new-homes/tx/houston/conroe/artavia-45-homesites | AV6: https://www.davidweekleyhomes.com/new-homes/tx/houston/conroe/artavia-45-homesites | AW6: he080bdf7b | AX6: 2026-09-27
A7: 6 | B7: houston | C7: hou-artavia | D7: ARTAVIA | E7: Montgomery | F7: Conroe | G7: 77302 | H7: AIRIA Development Company | I7: Conroe ISD | J7: David Weekley Homes | K7: b-houston-david-weekley-homes | L7: National builder | M7: Yes | N7: No | O7: No | Q7: hou-artavia#3 | R7: Reserve Collection | S7: 45 | T7: 45 | U7: Plan T103 | V7: 409990 | W7: 2105 | X7: =IF(W7>0,V7/W7,"") | Y7: 3 | Z7: 2 | AB7: =IF(Z7="","",Z7+0.5*N(AA7)) | AC7: 2 | AD7: 1 | AH7: =IF(AG7="","",1-V7/AG7) | AK7: 15130 London Gavroche Lane | AL7: 30.7 | AM7: Houston | AN7: 326778 | AO7: -0.0227 | AP7: 335775 | AQ7: 153 | AR7: 2842 | AU7: https://www.davidweekleyhomes.com/new-homes/tx/houston/conroe/artavia-45-homesites | AV7: https://www.davidweekleyhomes.com/new-homes/tx/houston/conroe/artavia-45-homesites | AW7: h29addb459 | AX7: 2026-09-27
A8: 7 | B8: houston | C8: hou-artavia | D8: ARTAVIA | E8: Montgomery | F8: Conroe | G8: 77302 | H8: AIRIA Development Company | I8: Conroe ISD | J8: David Weekley Homes | K8: b-houston-david-weekley-homes | L8: National builder | M8: Yes | N8: No | O8: No | Q8: hou-artavia#3 | R8: Reserve Collection | S8: 45 | T8: 45 | U8: Plan T101 | V8: 394990 | W8: 1713 | X8: =IF(W8>0,V8/W8,"") | Y8: 3 | Z8: 2 | AB8: =IF(Z8="","",Z8+0.5*N(AA8)) | AC8: 2 | AD8: 1 | AH8: =IF(AG8="","",1-V8/AG8) | AK8: 15007 Silvano Street | AL8: 30.7 | AM8: Houston | AN8: 326778 | AO8: -0.0227 | AP8: 335775 | AQ8: 153 | AR8: 2842 | AU8: https://www.davidweekleyhomes.com/new-homes/tx/houston/conroe/artavia-45-homesites | AV8: https://www.davidweekleyhomes.com/new-homes/tx/houston/conroe/artavia-45-homesites | AW8: h310e66e2b | AX8: 2026-09-27
A9: 8 | B9: houston | C9: hou-artavia | D9: ARTAVIA | E9: Montgomery | F9: Conroe | G9: 77302 | H9: AIRIA Development Company | I9: Conroe ISD | J9: David Weekley Homes | K9: b-houston-david-weekley-homes | L9: National builder | M9: Yes | N9: No | O9: No | Q9: hou-artavia#3 | R9: Reserve Collection | S9: 45 | T9: 45 | U9: Plan T102 | V9: 394990 | W9: 1910 | X9: =IF(W9>0,V9/W9,"") | Y9: 3 | Z9: 2 | AB9: =IF(Z9="","",Z9+0.5*N(AA9)) | AC9: 2 | AD9: 1 | AH9: =IF(AG9="","",1-V9/AG9) | AK9: 18319 Bon Brothers Drive | AL9: 30.7 | AM9: Houston | AN9: 326778 | AO9: -0.0227 | AP9: 335775 | AQ9: 153 | AR9: 2842 | AU9: https://www.davidweekleyhomes.com/new-homes/tx/houston/conroe/artavia-45-homesites | AV9: https://www.davidweekleyhomes.com/new-homes/tx/houston/conroe/artavia-45-homesites | AW9: hadcf4e27d | AX9: 2026-09-27
A10: 9 | B10: houston | C10: hou-artavia | D10: ARTAVIA | E10: Montgomery | F10: Conroe | G10: 77302 | H10: AIRIA Development Company | I10: Conroe ISD | J10: David Weekley Homes | K10: b-houston-david-weekley-homes | L10: National builder | M10: Yes | N10: No | O10: No | Q10: hou-artavia#4 | R10: Enclave Collection | S10: 50 | T10: 50 | U10: Plan T004 | V10: 459990 | W10: 2216 | X10: =IF(W10>0,V10/W10,"") | Y10: 4 | Z10: 3 | AA10: 1 | AB10: =IF(Z10="","",Z10+0.5*N(AA10)) | AC10: 2 | AD10: 1 | AE10: ready | AF10: Ready Now | AH10: =IF(AG10="","",1-V10/AG10) | AK10: 16138 Rita Road | AL10: 30.7 | AM10: Houston | AN10: 326778 | AO10: -0.0227 | AP10: 335775 | AQ10: 153 | AR10: 2842 | AU10: https://www.davidweekleyhomes.com/new-homes/tx/houston/conroe/artavia-50-homesites | AV10: https://www.davidweekleyhomes.com/new-homes/tx/houston/conroe/artavia-50-homesites | AW10: h2b9ac2c2d | AX10: 2026-09-27
A11: 10 | B11: houston | C11: hou-artavia | D11: ARTAVIA | E11: Montgomery | F11: Conroe | G11: 77302 | H11: AIRIA Development Company | I11: Conroe ISD | J11: David Weekley Homes | K11: b-houston-david-weekley-homes | L11: National builder | M11: Yes | N11: No | O11: No | Q11: hou-artavia#4 | R11: Enclave Collection | S11: 50 | T11: 50 | U11: Plan T010 | V11: 469990 | W11: 2618 | X11: =IF(W11>0,V11/W11,"") | Y11: 4 | Z11: 3 | AA11: 1 | AB11: =IF(Z11="","",Z11+0.5*N(AA11)) | AC11: 2 | AD11: 2 | AE11: ready | AF11: Ready Now | AH11: =IF(AG11="","",1-V11/AG11) | AK11: 16146 Rita Road | AL11: 30.7 | AM11: Houston | AN11: 326778 | AO11: -0.0227 | AP11: 335775 | AQ11: 153 | AR11: 2842 | AU11: https://www.davidweekleyhomes.com/new-homes/tx/houston/conroe/artavia-50-homesites | AV11: https://www.davidweekleyhomes.com/new-homes/tx/houston/conroe/artavia-50-homesites | AW11: h50041d7b8 | AX11: 2026-09-27
A12: 11 | B12: houston | C12: hou-artavia | D12: ARTAVIA | E12: Montgomery | F12: Conroe | G12: 77302 | H12: AIRIA Development Company | I12: Conroe ISD | J12: David Weekley Homes | K12: b-houston-david-weekley-homes | L12: National builder | M12: Yes | N12: No | O12: No | Q12: hou-artavia#4 | R12: Enclave Collection | S12: 50 | T12: 50 | U12: Plan T005 | V12: 449990 | W12: 2286 | X12: =IF(W12>0,V12/W12,"") | Y12: 3 | Z12: 2 | AA12: 1 | AB12: =IF(Z12="","",Z12+0.5*N(AA12)) | AC12: 3 | AD12: 1 | AE12: ready | AF12: Ready Now | AH12: =IF(AG12="","",1-V12/AG12) | AK12: 18607 Rumba Court | AL12: 30.7 | AM12: Houston | AN12: 326778 | AO12: -0.0227 | AP12: 335775 | AQ12: 153 | AR12: 2842 | AU12: https://www.davidweekleyhomes.com/new-homes/tx/houston/conroe/artavia-50-homesites | AV12: https://www.davidweekleyhomes.com/new-homes/tx/houston/conroe/artavia-50-homesites | AW12: h0ff7e7f82 | AX12: 2026-09-27
A13: 12 | B13: houston | C13: hou-artavia | D13: ARTAVIA | E13: Montgomery | F13: Conroe | G13: 77302 | H13: AIRIA Development Company | I13: Conroe ISD | J13: David Weekley Homes | K13: b-houston-david-weekley-homes | L13: National builder | M13: Yes | N13: No | O13: No | Q13: hou-artavia#4 | R13: Enclave Collection | S13: 50 | T13: 50 | U13: Plan T014 | V13: 517990 | W13: 3101 | X13: =IF(W13>0,V13/W13,"") | Y13: 5 | Z13: 4 | AB13: =IF(Z13="","",Z13+0.5*N(AA13)) | AC13: 4 | AD13: 2 | AH13: =IF(AG13="","",1-V13/AG13) | AK13: 18611 Rumba Court | AL13: 30.7 | AM13: Houston | AN13: 326778 | AO13: -0.0227 | AP13: 335775 | AQ13: 153 | AR13: 2842 | AU13: https://www.davidweekleyhomes.com/new-homes/tx/houston/conroe/artavia-50-homesites | AV13: https://www.davidweekleyhomes.com/new-homes/tx/houston/conroe/artavia-50-homesites | AW13: hb49ab8cb1 | AX13: 2026-09-27
A14: 13 | B14: houston | C14: hou-artavia | D14: ARTAVIA | E14: Montgomery | F14: Conroe | G14: 77302 | H14: AIRIA Development Company | I14: Conroe ISD | J14: David Weekley Homes | K14: b-houston-david-weekley-homes | L14: National builder | M14: Yes | N14: No | O14: No | Q14: hou-artavia#4 | R14: Enclave Collection | S14: 50 | T14: 50 | U14: Plan T008 | V14: 496990 | W14: 2545 | X14: =IF(W14>0,V14/W14,"") | Y14: 4 | Z14: 3 | AA14: 1 | AB14: =IF(Z14="","",Z14+0.5*N(AA14)) | AC14: 3 | AD14: 1 | AH14: =IF(AG14="","",1-V14/AG14) | AK14: 18606 Rumba Court | AL14: 30.7 | AM14: Houston | AN14: 326778 | AO14: -0.0227 | AP14: 335775 | AQ14: 153 | AR14: 2842 | AU14: https://www.davidweekleyhomes.com/new-homes/tx/houston/conroe/artavia-50-homesites | AV14: https://www.davidweekleyhomes.com/new-homes/tx/houston/conroe/artavia-50-homesites | AW14: h8a337a77f | AX14: 2026-09-27
A15: 14 | B15: houston | C15: hou-artavia | D15: ARTAVIA | E15: Montgomery | F15: Conroe | G15: 77302 | H15: AIRIA Development Company | I15: Conroe ISD | J15: David Weekley Homes | K15: b-houston-david-weekley-homes | L15: National builder | M15: Yes | N15: No | O15: No | Q15: hou-artavia#5 | R15: Parkview Collection | S15: 65 | T15: 65 | U15: Plan B679 | V15: 589990 | W15: 3121 | X15: =IF(W15>0,V15/W15,"") | Y15: 4 | Z15: 3 | AA15: 1 | AB15: =IF(Z15="","",Z15+0.5*N(AA15)) | AC15: 3 | AD15: 1 | AE15: ready | AF15: Ready Now | AH15: =IF(AG15="","",1-V15/AG15) | AK15: 15748 Terracotta Terrace Lane | AL15: 30.7 | AM15: Houston | AN15: 326778 | AO15: -0.0227 | AP15: 335775 | AQ15: 153 | AR15: 2842 | AU15: https://www.davidweekleyhomes.com/new-homes/tx/houston/conroe/artavia | AV15: https://www.davidweekleyhomes.com/new-homes/tx/houston/conroe/artavia | AW15: h6a2d65679 | AX15: 2026-09-27
A16: 15 | B16: houston | C16: hou-artavia | D16: ARTAVIA | E16: Montgomery | F16: Conroe | G16: 77302 | H16: AIRIA Development Company | I16: Conroe ISD | J16: David Weekley Homes | K16: b-houston-david-weekley-homes | L16: National builder | M16: Yes | N16: No | O16: No | Q16: hou-artavia#5 | R16: Parkview Collection | S16: 65 | T16: 65 | U16: Plan B679 | V16: 583990 | W16: 3100 | X16: =IF(W16>0,V16/W16,"") | Y16: 4 | Z16: 3 | AB16: =IF(Z16="","",Z16+0.5*N(AA16)) | AC16: 3 | AD16: 1 | AE16: ready | AF16: Ready Now | AH16: =IF(AG16="","",1-V16/AG16) | AK16: 15829 Moran Meadow Street | AL16: 30.7 | AM16: Houston | AN16: 326778 | AO16: -0.0227 | AP16: 335775 | AQ16: 153 | AR16: 2842 | AU16: https://www.davidweekleyhomes.com/new-homes/tx/houston/conroe/artavia | AV16: https://www.davidweekleyhomes.com/new-homes/tx/houston/conroe/artavia | AW16: h85506c7d7 | AX16: 2026-09-27
A17: 16 | B17: houston | C17: hou-artavia | D17: ARTAVIA | E17: Montgomery | F17: Conroe | G17: 77302 | H17: AIRIA Development Company | I17: Conroe ISD | J17: David Weekley Homes | K17: b-houston-david-weekley-homes | L17: National builder | M17: Yes | N17: No | O17: No | Q17: hou-artavia#5 | R17: Parkview Collection | S17: 65 | T17: 65 | U17: Plan B071 | V17: 624990 | W17: 3076 | X17: =IF(W17>0,V17/W17,"") | Y17: 4 | Z17: 3 | AB17: =IF(Z17="","",Z17+0.5*N(AA17)) | AC17: 4 | AD17: 1 | AE17: ready | AF17: Ready Now | AH17: =IF(AG17="","",1-V17/AG17) | AK17: 18023 Lobos Point Lane | AL17: 30.7 | AM17: Houston | AN17: 326778 | AO17: -0.0227 | AP17: 335775 | AQ17: 153 | AR17: 2842 | AU17: https://www.davidweekleyhomes.com/new-homes/tx/houston/conroe/artavia | AV17: https://www.davidweekleyhomes.com/new-homes/tx/houston/conroe/artavia | AW17: h19b7298a5 | AX17: 2026-09-27
A18: 17 | B18: houston | C18: hou-artavia | D18: ARTAVIA | E18: Montgomery | F18: Conroe | G18: 77302 | H18: AIRIA Development Company | I18: Conroe ISD | J18: David Weekley Homes | K18: b-houston-david-weekley-homes | L18: National builder | M18: Yes | N18: No | O18: No | Q18: hou-artavia#5 | R18: Parkview Collection | S18: 65 | T18: 65 | U18: Plan T045 | V18: 649990 | W18: 3317 | X18: =IF(W18>0,V18/W18,"") | Y18: 4 | Z18: 3 | AA18: 1 | AB18: =IF(Z18="","",Z18+0.5*N(AA18)) | AC18: 4 | AD18: 1 | AE18: ready | AF18: Ready Now | AH18: =IF(AG18="","",1-V18/AG18) | AK18: 18015 Lobos Point Lane | AL18: 30.7 | AM18: Houston | AN18: 326778 | AO18: -0.0227 | AP18: 335775 | AQ18: 153 | AR18: 2842 | AU18: https://www.davidweekleyhomes.com/new-homes/tx/houston/conroe/artavia | AV18: https://www.davidweekleyhomes.com/new-homes/tx/houston/conroe/artavia | AW18: hecce56ccd | AX18: 2026-09-27
A19: 18 | B19: houston | C19: hou-artavia | D19: ARTAVIA | E19: Montgomery | F19: Conroe | G19: 77302 | H19: AIRIA Development Company | I19: Conroe ISD | J19: David Weekley Homes | K19: b-houston-david-weekley-homes | L19: National builder | M19: Yes | N19: No | O19: No | Q19: hou-artavia#5 | R19: Parkview Collection | S19: 65 | T19: 65 | U19: Plan B443 | V19: 649990 | W19: 4086 | X19: =IF(W19>0,V19/W19,"") | Y19: 4 | Z19: 3 | AA19: 1 | AB19: =IF(Z19="","",Z19+0.5*N(AA19)) | AC19: 3 | AD19: 2 | AE19: ready | AF19: Ready Now | AH19: =IF(AG19="","",1-V19/AG19) | AK19: 15730 Terracotta Terrace Lane | AL19: 30.7 | AM19: Houston | AN19: 326778 | AO19: -0.0227 | AP19: 335775 | AQ19: 153 | AR19: 2842 | AU19: https://www.davidweekleyhomes.com/new-homes/tx/houston/conroe/artavia | AV19: https://www.davidweekleyhomes.com/new-homes/tx/houston/conroe/artavia | AW19: h0357f55ab | AX19: 2026-09-27
A20: 19 | B20: houston | C20: hou-artavia | D20: ARTAVIA | E20: Montgomery | F20: Conroe | G20: 77302 | H20: AIRIA Development Company | I20: Conroe ISD | J20: Highland Homes | K20: b-houston-highland-homes | L20: Two of three counts | M20: Yes | N20: Partly | O20: No | Q20: hou-artavia#6 | R20: 50ft. lots | S20: 50 | T20: 50 | U20: VanGogh Plan | V20: 484990 | W20: 2663 | X20: =IF(W20>0,V20/W20,"") | Y20: 4 | Z20: 3 | AB20: =IF(Z20="","",Z20+0.5*N(AA20)) | AC20: 2 | AD20: 1 | AE20: ready | AF20: Complete | AH20: =IF(AG20="","",1-V20/AG20) | AJ20: $30K Your Way! | AK20: 16642 Jolie Street | AL20: 30.7 | AM20: Houston | AN20: 326778 | AO20: -0.0227 | AP20: 335775 | AQ20: 153 | AR20: 2842 | AU20: https://www.highlandhomes.com/houston/conroe/artavia/50ft-lots/section | AV20: https://www.highlandhomes.com/houston/conroe/artavia/50ft-lots/section | AW20: h142491f78 | AX20: 2026-09-27
A21: 20 | B21: houston | C21: hou-artavia | D21: ARTAVIA | E21: Montgomery | F21: Conroe | G21: 77302 | H21: AIRIA Development Company | I21: Conroe ISD | J21: Highland Homes | K21: b-houston-highland-homes | L21: Two of three counts | M21: Yes | N21: Partly | O21: No | Q21: hou-artavia#6 | R21: 50ft. lots | S21: 50 | T21: 50 | U21: Davenport Plan | V21: 414990 | W21: 2317 | X21: =IF(W21>0,V21/W21,"") | Y21: 4 | Z21: 3 | AB21: =IF(Z21="","",Z21+0.5*N(AA21)) | AC21: 2 | AD21: 1 | AE21: ready | AF21: Move-in Ready | AH21: =IF(AG21="","",1-V21/AG21) | AJ21: $30K Your Way! | AK21: 16622 Jolie Street | AL21: 30.7 | AM21: Houston | AN21: 326778 | AO21: -0.0227 | AP21: 335775 | AQ21: 153 | AR21: 2842 | AU21: https://www.highlandhomes.com/houston/conroe/artavia/50ft-lots/section | AV21: https://www.highlandhomes.com/houston/conroe/artavia/50ft-lots/section | AW21: hb1ada6194 | AX21: 2026-09-27
A22: 21 | B22: houston | C22: hou-artavia | D22: ARTAVIA | E22: Montgomery | F22: Conroe | G22: 77302 | H22: AIRIA Development Company | I22: Conroe ISD | J22: Highland Homes | K22: b-houston-highland-homes | L22: Two of three counts | M22: Yes | N22: Partly | O22: No | Q22: hou-artavia#6 | R22: 50ft. lots | S22: 50 | T22: 50 | U22: Cambridge Plan | V22: 499990 | W22: 2982 | X22: =IF(W22>0,V22/W22,"") | Y22: 4 | Z22: 4 | AB22: =IF(Z22="","",Z22+0.5*N(AA22)) | AC22: 2 | AD22: 2 | AE22: ready | AF22: Move-in Ready | AH22: =IF(AG22="","",1-V22/AG22) | AJ22: $30K Your Way! | AK22: 16543 Mandora Lane | AL22: 30.7 | AM22: Houston | AN22: 326778 | AO22: -0.0227 | AP22: 335775 | AQ22: 153 | AR22: 2842 | AU22: https://www.highlandhomes.com/houston/conroe/artavia/50ft-lots/section | AV22: https://www.highlandhomes.com/houston/conroe/artavia/50ft-lots/section | AW22: hfb86be92f | AX22: 2026-09-27
A23: 22 | B23: houston | C23: hou-artavia | D23: ARTAVIA | E23: Montgomery | F23: Conroe | G23: 77302 | H23: AIRIA Development Company | I23: Conroe ISD | J23: Highland Homes | K23: b-houston-highland-homes | L23: Two of three counts | M23: Yes | N23: Partly | O23: No | Q23: hou-artavia#6 | R23: 50ft. lots | S23: 50 | T23: 50 | U23: Matisse Plan | V23: 424990 | W23: 2264 | X23: =IF(W23>0,V23/W23,"") | Y23: 4 | Z23: 2 | AB23: =IF(Z23="","",Z23+0.5*N(AA23)) | AC23: 2 | AD23: 1 | AE23: ready | AF23: Move-in Ready | AH23: =IF(AG23="","",1-V23/AG23) | AJ23: $30K Your Way! | AK23: 16519 Mandora Lane | AL23: 30.7 | AM23: Houston | AN23: 326778 | AO23: -0.0227 | AP23: 335775 | AQ23: 153 | AR23: 2842 | AU23: https://www.highlandhomes.com/houston/conroe/artavia/50ft-lots/section | AV23: https://www.highlandhomes.com/houston/conroe/artavia/50ft-lots/section | AW23: h65c45f2cd | AX23: 2026-09-27
A24: 23 | B24: houston | C24: hou-artavia | D24: ARTAVIA | E24: Montgomery | F24: Conroe | G24: 77302 | H24: AIRIA Development Company | I24: Conroe ISD | J24: Highland Homes | K24: b-houston-highland-homes | L24: Two of three counts | M24: Yes | N24: Partly | O24: No | Q24: hou-artavia#7 | R24: 60ft. lots | S24: 60 | T24: 60 | U24: Ramsey Plan | V24: 524990 | W24: 2862 | X24: =IF(W24>0,V24/W24,"") | Y24: 4 | Z24: 3 | AA24: 1 | AB24: =IF(Z24="","",Z24+0.5*N(AA24)) | AC24: 3 | AD24: 1 | AE24: ready | AF24: Complete | AH24: =IF(AG24="","",1-V24/AG24) | AJ24: $30K Your Way! | AK24: 15630 Broadway Bend Drive | AL24: 30.7 | AM24: Houston | AN24: 326778 | AO24: -0.0227 | AP24: 335775 | AQ24: 153 | AR24: 2842 | AU24: https://www.highlandhomes.com/houston/conroe/artavia/60ft-lots/section | AV24: https://www.highlandhomes.com/houston/conroe/artavia/60ft-lots/section | AW24: hdab1c5012 | AX24: 2026-09-27
A25: 24 | B25: houston | C25: hou-artavia | D25: ARTAVIA | E25: Montgomery | F25: Conroe | G25: 77302 | H25: AIRIA Development Company | I25: Conroe ISD | J25: Highland Homes | K25: b-houston-highland-homes | L25: Two of three counts | M25: Yes | N25: Partly | O25: No | Q25: hou-artavia#7 | R25: 60ft. lots | S25: 60 | T25: 60 | U25: Birchwood Plan | V25: 549990 | W25: 2815 | X25: =IF(W25>0,V25/W25,"") | Y25: 4 | Z25: 3 | AA25: 1 | AB25: =IF(Z25="","",Z25+0.5*N(AA25)) | AC25: 3 | AD25: 1 | AE25: ready | AF25: Move-in Ready | AH25: =IF(AG25="","",1-V25/AG25) | AJ25: $30K Your Way! | AK25: 16435 Cat Court | AL25: 30.7 | AM25: Houston | AN25: 326778 | AO25: -0.0227 | AP25: 335775 | AQ25: 153 | AR25: 2842 | AU25: https://www.highlandhomes.com/houston/conroe/artavia/60ft-lots/section | AV25: https://www.highlandhomes.com/houston/conroe/artavia/60ft-lots/section | AW25: h84ae9dc89 | AX25: 2026-09-27
A26: 25 | B26: houston | C26: hou-artavia | D26: ARTAVIA | E26: Montgomery | F26: Conroe | G26: 77302 | H26: AIRIA Development Company | I26: Conroe ISD | J26: Highland Homes | K26: b-houston-highland-homes | L26: Two of three counts | M26: Yes | N26: Partly | O26: No | Q26: hou-artavia#7 | R26: 60ft. lots | S26: 60 | T26: 60 | U26: Ramsey Plan | V26: 564990 | W26: 2881 | X26: =IF(W26>0,V26/W26,"") | Y26: 4 | Z26: 3 | AA26: 1 | AB26: =IF(Z26="","",Z26+0.5*N(AA26)) | AC26: 3 | AD26: 1 | AH26: =IF(AG26="","",1-V26/AG26) | AJ26: $30K Your Way! | AK26: 18918 Moonriver Street | AL26: 30.7 | AM26: Houston | AN26: 326778 | AO26: -0.0227 | AP26: 335775 | AQ26: 153 | AR26: 2842 | AU26: https://www.highlandhomes.com/houston/conroe/artavia/60ft-lots/section | AV26: https://www.highlandhomes.com/houston/conroe/artavia/60ft-lots/section | AW26: h26c1e8a5e | AX26: 2026-09-27
A27: 26 | B27: houston | C27: hou-artavia | D27: ARTAVIA | E27: Montgomery | F27: Conroe | G27: 77302 | H27: AIRIA Development Company | I27: Conroe ISD | J27: Highland Homes | K27: b-houston-highland-homes | L27: Two of three counts | M27: Yes | N27: Partly | O27: No | Q27: hou-artavia#7 | R27: 60ft. lots | S27: 60 | T27: 60 | U27: Bradford Plan | V27: 559990 | W27: 3057 | X27: =IF(W27>0,V27/W27,"") | Y27: 4 | Z27: 3 | AA27: 1 | AB27: =IF(Z27="","",Z27+0.5*N(AA27)) | AC27: 3 | AD27: 1 | AH27: =IF(AG27="","",1-V27/AG27) | AJ27: $30K Your Way! | AK27: 18206 Hairpin Banksia Lane | AL27: 30.7 | AM27: Houston | AN27: 326778 | AO27: -0.0227 | AP27: 335775 | AQ27: 153 | AR27: 2842 | AU27: https://www.highlandhomes.com/houston/conroe/artavia/60ft-lots/section | AV27: https://www.highlandhomes.com/houston/conroe/artavia/60ft-lots/section | AW27: h7f8dd0326 | AX27: 2026-09-27
A28: 27 | B28: houston | C28: hou-artavia | D28: ARTAVIA | E28: Montgomery | F28: Conroe | G28: 77302 | H28: AIRIA Development Company | I28: Conroe ISD | J28: Jamestown Estate Homes | K28: b-houston-jamestown-estate-homes | L28: Two of three counts | M28: Partly | N28: Yes | O28: No | Q28: hou-artavia#10 | S28: 80 | T28: 80 | V28: 850000 | W28: 3536 | X28: =IF(W28>0,V28/W28,"") | Y28: 4 | AB28: =IF(Z28="","",Z28+0.5*N(AA28)) | AC28: 3 | AH28: =IF(AG28="","",1-V28/AG28) | AK28: 15910 Mango Tango Dr | AL28: 30.7 | AM28: Houston | AN28: 326778 | AO28: -0.0227 | AP28: 335775 | AQ28: 153 | AR28: 2842 | AU28: https://jamestownestatehomes.com/artavia-homebuilders/ | AV28: https://jamestownestatehomes.com/artavia-homebuilders/ | AW28: he8dae311f | AX28: 2026-09-27
A29: 28 | B29: houston | C29: hou-artavia | D29: ARTAVIA | E29: Montgomery | F29: Conroe | G29: 77302 | H29: AIRIA Development Company | I29: Conroe ISD | J29: Jamestown Estate Homes | K29: b-houston-jamestown-estate-homes | L29: Two of three counts | M29: Partly | N29: Yes | O29: No | Q29: hou-artavia#10 | S29: 80 | T29: 80 | V29: 885000 | W29: 3554 | X29: =IF(W29>0,V29/W29,"") | Y29: 4 | AB29: =IF(Z29="","",Z29+0.5*N(AA29)) | AC29: 3 | AH29: =IF(AG29="","",1-V29/AG29) | AL29: 30.7 | AM29: Houston | AN29: 326778 | AO29: -0.0227 | AP29: 335775 | AQ29: 153 | AR29: 2842 | AU29: https://jamestownestatehomes.com/artavia-homebuilders/ | AV29: https://jamestownestatehomes.com/artavia-homebuilders/ | AW29: h414962bc3 | AX29: 2026-09-27
A30: 29 | B30: houston | C30: hou-artavia | D30: ARTAVIA | E30: Montgomery | F30: Conroe | G30: 77302 | H30: AIRIA Development Company | I30: Conroe ISD | J30: Jamestown Estate Homes | K30: b-houston-jamestown-estate-homes | L30: Two of three counts | M30: Partly | N30: Yes | O30: No | Q30: hou-artavia#10 | S30: 80 | T30: 80 | V30: 1059990 | W30: 4318 | X30: =IF(W30>0,V30/W30,"") | Y30: 5 | Z30: 5 | AA30: 1 | AB30: =IF(Z30="","",Z30+0.5*N(AA30)) | AC30: 3 | AH30: =IF(AG30="","",1-V30/AG30) | AL30: 30.7 | AM30: Houston | AN30: 326778 | AO30: -0.0227 | AP30: 335775 | AQ30: 153 | AR30: 2842 | AU30: https://jamestownestatehomes.com/artavia-homebuilders/ | AV30: https://jamestownestatehomes.com/artavia-homebuilders/ | AW30: h4670f7814 | AX30: 2026-09-27
A31: 30 | B31: houston | C31: hou-artavia | D31: ARTAVIA | E31: Montgomery | F31: Conroe | G31: 77302 | H31: AIRIA Development Company | I31: Conroe ISD | J31: Lennar | K31: b-houston-lennar | L31: Lennar and the firms it owns | M31: Yes | N31: No | O31: Yes | P31: Lennar | Q31: hou-artavia#11 | R31: Fairway Collection | S31: 55 | T31: 55 | U31: Cabotll | V31: 330991 | W31: 2386 | X31: =IF(W31>0,V31/W31,"") | Y31: 3 | Z31: 2 | AA31: 1 | AB31: =IF(Z31="","",Z31+0.5*N(AA31)) | AH31: =IF(AG31="","",1-V31/AG31) | AK31: 15047 Goujon Gates Drive | AL31: 30.7 | AM31: Houston | AN31: 326778 | AO31: -0.0227 | AP31: 335775 | AQ31: 153 | AR31: 2842 | AU31: https://www.lennar.com/new-homes/texas/houston/conroe/artavia | AV31: https://www.lennar.com/new-homes/texas/houston/conroe/artavia | AW31: hbf4ca5b27 | AX31: 2026-09-27
A32: 31 | B32: houston | C32: hou-artavia | D32: ARTAVIA | E32: Montgomery | F32: Conroe | G32: 77302 | H32: AIRIA Development Company | I32: Conroe ISD | J32: Lennar | K32: b-houston-lennar | L32: Lennar and the firms it owns | M32: Yes | N32: No | O32: Yes | P32: Lennar | Q32: hou-artavia#11 | R32: Fairway Collection | S32: 55 | T32: 55 | U32: Cabotll | V32: 340990 | W32: 2386 | X32: =IF(W32>0,V32/W32,"") | Y32: 3 | Z32: 2 | AA32: 1 | AB32: =IF(Z32="","",Z32+0.5*N(AA32)) | AH32: =IF(AG32="","",1-V32/AG32) | AK32: 14948 Calluna Heather Lane | AL32: 30.7 | AM32: Houston | AN32: 326778 | AO32: -0.0227 | AP32: 335775 | AQ32: 153 | AR32: 2842 | AU32: https://www.lennar.com/new-homes/texas/houston/conroe/artavia | AV32: https://www.lennar.com/new-homes/texas/houston/conroe/artavia | AW32: h71c3e5995 | AX32: 2026-09-27
A33: 32 | B33: houston | C33: hou-artavia | D33: ARTAVIA | E33: Montgomery | F33: Conroe | G33: 77302 | H33: AIRIA Development Company | I33: Conroe ISD | J33: Lennar | K33: b-houston-lennar | L33: Lennar and the firms it owns | M33: Yes | N33: No | O33: Yes | P33: Lennar | Q33: hou-artavia#11 | R33: Fairway Collection | S33: 55 | T33: 55 | U33: Cabotll | V33: 345990 | W33: 2386 | X33: =IF(W33>0,V33/W33,"") | Y33: 3 | Z33: 2 | AA33: 1 | AB33: =IF(Z33="","",Z33+0.5*N(AA33)) | AH33: =IF(AG33="","",1-V33/AG33) | AK33: 17915 Rillette Road | AL33: 30.7 | AM33: Houston | AN33: 326778 | AO33: -0.0227 | AP33: 335775 | AQ33: 153 | AR33: 2842 | AU33: https://www.lennar.com/new-homes/texas/houston/conroe/artavia | AV33: https://www.lennar.com/new-homes/texas/houston/conroe/artavia | AW33: h068f9e89c | AX33: 2026-09-27
A34: 33 | B34: houston | C34: hou-artavia | D34: ARTAVIA | E34: Montgomery | F34: Conroe | G34: 77302 | H34: AIRIA Development Company | I34: Conroe ISD | J34: Lennar | K34: b-houston-lennar | L34: Lennar and the firms it owns | M34: Yes | N34: No | O34: Yes | P34: Lennar | Q34: hou-artavia#11 | R34: Fairway Collection | S34: 55 | T34: 55 | U34: Glenbrookll | V34: 356990 | W34: 2517 | X34: =IF(W34>0,V34/W34,"") | Y34: 3 | Z34: 2 | AA34: 1 | AB34: =IF(Z34="","",Z34+0.5*N(AA34)) | AE34: ready | AF34: Move-in ready | AH34: =IF(AG34="","",1-V34/AG34) | AK34: 17859 Aile Pierre Pass | AL34: 30.7 | AM34: Houston | AN34: 326778 | AO34: -0.0227 | AP34: 335775 | AQ34: 153 | AR34: 2842 | AU34: https://www.lennar.com/new-homes/texas/houston/conroe/artavia | AV34: https://www.lennar.com/new-homes/texas/houston/conroe/artavia | AW34: h7a0999d05 | AX34: 2026-09-27
A35: 34 | B35: houston | C35: hou-artavia | D35: ARTAVIA | E35: Montgomery | F35: Conroe | G35: 77302 | H35: AIRIA Development Company | I35: Conroe ISD | J35: Ravenna Homes | K35: b-houston-ravenna-homes | L35: Two of three counts | M35: Partly | N35: Partly | O35: No | Q35: hou-artavia#15 | R35: ARTAVIA 70' | S35: 70 | T35: 70 | U35: Plan 4195 | V35: 788900 | W35: 4195 | X35: =IF(W35>0,V35/W35,"") | Y35: 2 | Z35: 2 | AB35: =IF(Z35="","",Z35+0.5*N(AA35)) | AD35: 2 | AE35: ready | AF35: complete | AG35: 870900 | AH35: =IF(AG35="","",1-V35/AG35) | AK35: 15607 Early Bird Lane | AL35: 30.7 | AM35: Houston | AN35: 326778 | AO35: -0.0227 | AP35: 335775 | AQ35: 153 | AR35: 2842 | AU35: https://www.ravennahomes.com/communities/artavia-70/ | AV35: https://www.ravennahomes.com/communities/artavia-70/ | AW35: h97788cc92 | AX35: 2026-09-27
A36: 35 | B36: houston | C36: hou-artavia | D36: ARTAVIA | E36: Montgomery | F36: Conroe | G36: 77302 | H36: AIRIA Development Company | I36: Conroe ISD | J36: Ravenna Homes | K36: b-houston-ravenna-homes | L36: Two of three counts | M36: Partly | N36: Partly | O36: No | Q36: hou-artavia#15 | R36: ARTAVIA 70' | S36: 70 | T36: 70 | U36: Plan 3865 | V36: 850000 | W36: 4013 | X36: =IF(W36>0,V36/W36,"") | Y36: 2 | Z36: 2 | AB36: =IF(Z36="","",Z36+0.5*N(AA36)) | AC36: 4 | AD36: 2 | AE36: ready | AF36: complete | AG36: 931900 | AH36: =IF(AG36="","",1-V36/AG36) | AK36: 15707 Dandelion Dreams Street | AL36: 30.7 | AM36: Houston | AN36: 326778 | AO36: -0.0227 | AP36: 335775 | AQ36: 153 | AR36: 2842 | AU36: https://www.ravennahomes.com/communities/artavia-70/ | AV36: https://www.ravennahomes.com/communities/artavia-70/ | AW36: h9674ebd10 | AX36: 2026-09-27
A37: 36 | B37: houston | C37: hou-artavia | D37: ARTAVIA | E37: Montgomery | F37: Conroe | G37: 77302 | H37: AIRIA Development Company | I37: Conroe ISD | J37: Ravenna Homes | K37: b-houston-ravenna-homes | L37: Two of three counts | M37: Partly | N37: Partly | O37: No | Q37: hou-artavia#15 | R37: ARTAVIA 70' | S37: 70 | T37: 70 | U37: Plan 4094 | V37: 849900 | W37: 4094 | X37: =IF(W37>0,V37/W37,"") | AB37: =IF(Z37="","",Z37+0.5*N(AA37)) | AC37: 4 | AD37: 2 | AE37: ready | AF37: complete | AG37: 857900 | AH37: =IF(AG37="","",1-V37/AG37) | AL37: 30.7 | AM37: Houston | AN37: 326778 | AO37: -0.0227 | AP37: 335775 | AQ37: 153 | AR37: 2842 | AU37: https://www.ravennahomes.com/communities/artavia-70/ | AV37: https://www.ravennahomes.com/communities/artavia-70/ | AW37: had93dbf29 | AX37: 2026-09-27
A38: 37 | B38: houston | C38: hou-artavia | D38: ARTAVIA | E38: Montgomery | F38: Conroe | G38: 77302 | H38: AIRIA Development Company | I38: Conroe ISD | J38: Ravenna Homes | K38: b-houston-ravenna-homes | L38: Two of three counts | M38: Partly | N38: Partly | O38: No | Q38: hou-artavia#15 | R38: ARTAVIA 70' | S38: 70 | T38: 70 | U38: Plan 4290 | V38: 878900 | W38: 4290 | X38: =IF(W38>0,V38/W38,"") | AB38: =IF(Z38="","",Z38+0.5*N(AA38)) | AC38: 1 | AD38: 1 | AE38: ready | AF38: completed | AG38: 886900 | AH38: =IF(AG38="","",1-V38/AG38) | AK38: 17576 Watercolor Way | AL38: 30.7 | AM38: Houston | AN38: 326778 | AO38: -0.0227 | AP38: 335775 | AQ38: 153 | AR38: 2842 | AU38: https://www.ravennahomes.com/communities/artavia-70/ | AV38: https://www.ravennahomes.com/communities/artavia-70/ | AW38: h817279876 | AX38: 2026-09-27
A39: 38 | B39: houston | C39: hou-artavia | D39: ARTAVIA | E39: Montgomery | F39: Conroe | G39: 77302 | H39: AIRIA Development Company | I39: Conroe ISD | J39: Westin Homes | K39: b-houston-westin-homes | L39: Two of three counts | M39: Yes | N39: Partly | O39: No | Q39: hou-artavia#16 | R39: ARTAVIA 40' | S39: 40 | T39: 40 | U39: The Haven X | V39: 419630 | W39: 2580 | X39: =IF(W39>0,V39/W39,"") | Y39: 4 | Z39: 3 | AA39: 1 | AB39: =IF(Z39="","",Z39+0.5*N(AA39)) | AC39: 2 | AH39: =IF(AG39="","",1-V39/AG39) | AK39: 15819 Swan Lake Lane | AL39: 30.7 | AM39: Houston | AN39: 326778 | AO39: -0.0227 | AP39: 335775 | AQ39: 153 | AR39: 2842 | AU39: https://www.westin-homes.com/communities/houston/artavia/artavia-40 | AV39: https://www.westin-homes.com/communities/houston/artavia/artavia-40 | AW39: h001de6d11 | AX39: 2026-09-27
A40: 39 | B40: houston | C40: hou-artavia | D40: ARTAVIA | E40: Montgomery | F40: Conroe | G40: 77302 | H40: AIRIA Development Company | I40: Conroe ISD | J40: Westin Homes | K40: b-houston-westin-homes | L40: Two of three counts | M40: Yes | N40: Partly | O40: No | Q40: hou-artavia#16 | R40: ARTAVIA 40' | S40: 40 | T40: 40 | U40: The Dominion | V40: 439496 | W40: 2600 | X40: =IF(W40>0,V40/W40,"") | Y40: 4 | Z40: 3 | AA40: 1 | AB40: =IF(Z40="","",Z40+0.5*N(AA40)) | AC40: 2 | AH40: =IF(AG40="","",1-V40/AG40) | AK40: 15710 Juliet Court | AL40: 30.7 | AM40: Houston | AN40: 326778 | AO40: -0.0227 | AP40: 335775 | AQ40: 153 | AR40: 2842 | AU40: https://www.westin-homes.com/communities/houston/artavia/artavia-40 | AV40: https://www.westin-homes.com/communities/houston/artavia/artavia-40 | AW40: h18d2705b2 | AX40: 2026-09-27
...

Sheet ProductLines
A1: line_id | B1: market | C1: community_id | D1: community | E1: builder | F1: product_line | G1: lot_widths_ft | H1: lot_width_ft | I1: stories_offered | J1: from_price | K1: from_is_band_floor | L1: from_text | M1: to_price | N1: to_text | O1: sqft_min | P1: sqft_max | Q1: n_plans | R1: qmi_listed | S1: qmi_read | T1: qmi_median_ppsf | U1: incentive_text | V1: source_url | W1: read_on
A2: hou-artavia#1 | B2: houston | C2: hou-artavia | D2: ARTAVIA | E2: Beazer Homes | G2: 65 | H2: 65 | J2: 487990 | L2: Starting $487,990 | M2: 568701 | N2: $568,701 (quick move-in, Northcliffe) | O2: 2754 | P2: 3908 | R2: 3 | S2: 3 | T2: 146 | U2: For a limited time, receive 50% off options up to $100,000 for your new to-be-built home when you use a Choice Lender!* | V2: https://www.beazer.com/houston-TX/conroe/artavia | W2: 2026-09-27
A3: hou-artavia#2 | B3: houston | C3: hou-artavia | D3: ARTAVIA | E3: Chesmar Homes | G3: 55 | H3: 55 | J3: 379990 | L3: Starting From: $379,990 | O3: 2086 | P3: 3107 | S3: 0 | U3: 4.999% (5.737% APR) FHA 30yr, fixed-rate special financing on select homes! | V3: https://www.chesmar.com/texas/houston-new-homes/conroe/artavia/ | W3: 2026-09-27
A4: hou-artavia#3 | B4: houston | C4: hou-artavia | D4: ARTAVIA | E4: David Weekley Homes | F4: Reserve Collection | G4: 45 | H4: 45 | I4: 1, 2 | J4: 354990 | L4: From: $354,990 | M4: 449990 | N4: $449,990 (quick move-in) | O4: 1713 | P4: 2888 | Q4: 7 | R4: 7 | S4: 5 | T4: 195 | V4: https://www.davidweekleyhomes.com/new-homes/tx/houston/conroe/artavia-45-homesites | W4: 2026-09-27
A5: hou-artavia#4 | B5: houston | C5: hou-artavia | D5: ARTAVIA | E5: David Weekley Homes | F5: Enclave Collection | G5: 50 | H5: 50 | I5: 1, 2 | J5: 422990 | L5: From: $422,990 | M5: 524990 | N5: From: $524,990 (highest plan) | O5: 2212 | P5: 3335 | Q5: 9 | R5: 9 | S5: 5 | T5: 195 | V5: https://www.davidweekleyhomes.com/new-homes/tx/houston/conroe/artavia-50-homesites | W5: 2026-09-27
A6: hou-artavia#5 | B6: houston | C6: hou-artavia | D6: ARTAVIA | E6: David Weekley Homes | F6: Parkview Collection | G6: 65 | H6: 65 | I6: 1, 2 | J6: 559990 | L6: From: $559,990 | M6: 674990 | N6: $674,990 (quick move-in) | O6: 2861 | P6: 4086 | Q6: 9 | R6: 10 | S6: 5 | T6: 189 | V6: https://www.davidweekleyhomes.com/new-homes/tx/houston/conroe/artavia | W6: 2026-09-27
A7: hou-artavia#6 | B7: houston | C7: hou-artavia | D7: ARTAVIA | E7: Highland Homes | F7: 50ft. lots | G7: 50 | H7: 50 | I7: 1, 2 | J7: 394990 | L7: from the $390s; lowest plan starting at $394,990 | M7: 499990 | N7: $499,990 (quick move-in, Cambridge Plan) | O7: 2164 | P7: 3440 | Q7: 17 | R7: 4 | S7: 4 | T7: 180 | U7: $30K Your Way! | V7: https://www.highlandhomes.com/houston/conroe/artavia/50ft-lots/section | W7: 2026-09-27
A8: hou-artavia#7 | B8: houston | C8: hou-artavia | D8: ARTAVIA | E8: Highland Homes | F8: 60ft. lots | G8: 60 | H8: 60 | I8: 1, 2 | J8: 503990 | L8: from the $500s; lowest plan starting at $503,990 | M8: 606990 | N8: Starting at $606,990 (highest plan) | O8: 2611 | P8: 3918 | Q8: 15 | R8: 4 | S8: 4 | T8: 189 | U8: $30K Your Way! | V8: https://www.highlandhomes.com/houston/conroe/artavia/60ft-lots/section | W8: 2026-09-27
A9: hou-artavia#8 | B9: houston | C9: hou-artavia | D9: ARTAVIA | E9: J. Patrick Homes | F9: ARTAVIA 55' lots | G9: 55 | H9: 55 | I9: 1, 2 | J9: 490000 | K9: yes | L9: from the $490s | O9: 2178 | P9: 3400 | Q9: 7 | S9: 0 | V9: https://www.jpatrickhomes.com/communities/artavia-55-lots/ | W9: 2026-09-27
A10: hou-artavia#9 | B10: houston | C10: hou-artavia | D10: ARTAVIA | E10: J. Patrick Homes | F10: ARTAVIA 70' lots | G10: 70 | H10: 70 | I10: 1, 2 | J10: 590000 | K10: yes | L10: from the $590s | O10: 2802 | P10: 4683 | Q10: 17 | S10: 0 | V10: https://www.jpatrickhomes.com/communities/artavia-70-lots/ | W10: 2026-09-27
A11: hou-artavia#10 | B11: houston | C11: hou-artavia | D11: ARTAVIA | E11: Jamestown Estate Homes | G11: 80 | H11: 80 | J11: 850000 | L11: Priced at $850,000 (available home); community site: 80' Lots from the $800's | M11: 1059990 | N11: Priced at $1,059,990 | Q11: 9 | R11: 3 | S11: 3 | T11: 245 | V11: https://jamestownestatehomes.com/artavia-homebuilders/ | W11: 2026-09-27
A12: hou-artavia#11 | B12: houston | C12: hou-artavia | D12: ARTAVIA | E12: Lennar | F12: Fairway Collection | G12: 55 | H12: 55 | J12: 330991 | L12: $330,991 - $418,990 | M12: 418990 | N12: $330,991 - $418,990 | O12: 2386 | P12: 2795 | Q12: 6 | R12: 10 | S12: 4 | T12: 142 | V12: https://www.lennar.com/new-homes/texas/houston/conroe/artavia | W12: 2026-09-27
A13: hou-artavia#12 | B13: houston | C13: hou-artavia | D13: ARTAVIA | E13: Perry Homes | F13: Artavia 45' | G13: 45 | H13: 45 | I13: 1, 2 | J13: 390000 | K13: yes | L13: From the $390s | O13: 1900 | P13: 2800 | S13: 0 | U13: Up to $55,000 for a limited time. Flex Cash* AND 4.99% rate (5.178% APR) | V13: https://www.perryhomes.com/new-homes/texas/houston/artavia | W13: 2026-09-27
A14: hou-artavia#13 | B14: houston | C14: hou-artavia | D14: ARTAVIA | E14: Perry Homes | F14: Artavia 50' | G14: 50 | H14: 50 | I14: 1, 2 | J14: 440000 | K14: yes | L14: From the $440s | O14: 2100 | P14: 3100 | S14: 0 | U14: Up to $55,000 for a limited time. Flex Cash* AND 4.99% rate (5.178% APR) | V14: https://www.perryhomes.com/new-homes/texas/houston/artavia | W14: 2026-09-27
A15: hou-artavia#14 | B15: houston | C15: hou-artavia | D15: ARTAVIA | E15: Perry Homes | F15: Artavia 55' - Valencia | G15: 55 | H15: 55 | I15: 1, 2 | J15: 540000 | K15: yes | L15: From the $540s | O15: 2600 | P15: 3500 | S15: 0 | U15: Up to $55,000 for a limited time. Flex Cash* AND 4.99% rate (5.178% APR) | V15: https://www.perryhomes.com/new-homes/texas/houston/artavia | W15: 2026-09-27
A16: hou-artavia#15 | B16: houston | C16: hou-artavia | D16: ARTAVIA | E16: Ravenna Homes | F16: ARTAVIA 70' | G16: 70 | H16: 70 | J16: 600000 | K16: yes | L16: From the $600's | M16: 878900 | N16: Now: $878,900 | O16: 3200 | P16: 4200 | R16: 4 | S16: 4 | T16: 206 | V16: https://www.ravennahomes.com/communities/artavia-70/ | W16: 2026-09-27
A17: hou-artavia#16 | B17: houston | C17: hou-artavia | D17: ARTAVIA | E17: Westin Homes | F17: ARTAVIA 40' | G17: 40 | H17: 40 | J17: 464990 | L17: Starting from $464,990 (lowest plan) | M17: 490990 | N17: Starting from $490,990 (highest plan) | O17: 2580 | P17: 2800 | Q17: 7 | R17: 5 | S17: 5 | T17: 173 | V17: https://www.westin-homes.com/communities/houston/artavia/artavia-40 | W17: 2026-09-27
A18: hou-artavia#17 | B18: houston | C18: hou-artavia | D18: ARTAVIA | E18: Westin Homes | F18: ARTAVIA 60' | G18: 60 | H18: 60 | J18: 558990 | L18: Starting from $558,990 (lowest plan) | M18: 612990 | N18: Starting from $612,990 (highest plan) | O18: 2818 | P18: 3788 | Q18: 6 | R18: 6 | S18: 5 | T18: 163 | V18: https://www.westin-homes.com/communities/houston/artavia/artavia-60 | W18: 2026-09-27
A19: hou-artavia#18 | B19: houston | C19: hou-artavia | D19: ARTAVIA | E19: Westin Homes | F19: ARTAVIA 65' Art Collection | G19: 65 | H19: 65 | J19: 745990 | L19: Starting from $745,990 (lowest plan) | M19: 818990 | N19: Starting from $818,990 (highest plan) | O19: 3568 | P19: 4500 | Q19: 8 | R19: 2 | S19: 2 | T19: 184 | V19: https://www.westin-homes.com/communities/houston/artavia/artavia-65-art-collection | W19: 2026-09-27
A20: hou-amira#1 | B20: houston | C20: hou-amira | D20: Amira | E20: Beazer Homes | F20: Amira 45' and 50' Homesites | G20: 45, 50 | J20: 349067 | L20: Starting $349,067 | M20: 548462 | N20: $548,462 (Sedona, quick move-in, 50' homesites) | O20: 1767 | P20: 3196 | R20: 14 | S20: 5 | T20: 182 | U20: For a limited time, receive up to $75,000 in options on your new to-be-built home when you use a Choice Lender!* | V20: https://www.beazer.com/houston-TX/tomball/amira | W20: 2026-09-27
A21: hou-amira#2 | B21: houston | C21: hou-amira | D21: Amira | E21: Perry Homes | F21: Amira 45' | G21: 45 | H21: 45 | J21: 370000 | K21: yes | L21: From the $370s | O21: 2000 | P21: 2100 | S21: 0 | U21: Up to $55,000 in incentives. Flex cash and low rate available for a limited time. | V21: https://www.perryhomes.com/new-homes/texas/houston/amira/amira-45 | W21: 2026-09-27
A22: hou-anniston#1 | B22: houston | C22: hou-anniston | D22: Anniston | E22: Lennar | F22: Cottage Collection | J22: 219991 | L22: From $219,991 | M22: 288990 | N22: $288,990 | O22: 1311 | P22: 2039 | Q22: 5 | R22: 8 | S22: 5 | T22: 159 | V22: https://www.lennar.com/new-homes/texas/houston/katy/anniston/cottage-collection | W22: 2026-09-27
A23: hou-anniston#2 | B23: houston | C23: hou-anniston | D23: Anniston | E23: Lennar | F23: Watermill Collection | J23: 235990 | L23: From $235,990 | M23: 291990 | N23: $291,990 | O23: 1084 | P23: 1968 | Q23: 6 | R23: 8 | S23: 5 | T23: 156 | V23: https://www.lennar.com/new-homes/texas/houston/katy/anniston/watermill-collection | W23: 2026-09-27
A24: hou-anniston#3 | B24: houston | C24: hou-anniston | D24: Anniston | E24: Lennar | F24: Classic Collection | J24: 277990 | L24: From $277,990 | M24: 422990 | N24: $422,990 | O24: 1602 | P24: 3223 | Q24: 6 | R24: 10 | S24: 5 | T24: 146 | V24: https://www.lennar.com/new-homes/texas/houston/katy/anniston/classic-collection | W24: 2026-09-27
A25: hou-anniston#4 | B25: houston | C25: hou-anniston | D25: Anniston | E25: Lennar | F25: Eventide Collection | J25: 276990 | L25: From $276,990 | M25: 356990 | N25: $356,990 | O25: 1572 | P25: 2637 | Q25: 7 | R25: 7 | S25: 5 | T25: 155 | V25: https://www.lennar.com/new-homes/texas/houston/katy/anniston/eventide-collection | W25: 2026-09-27
A26: hou-anniston#5 | B26: houston | C26: hou-anniston | D26: Anniston | E26: Lennar | F26: Richmond Collection | J26: 299990 | L26: From $299,990 | M26: 410990 | N26: $410,990 | O26: 2013 | P26: 3198 | Q26: 7 | R26: 8 | S26: 5 | T26: 133 | V26: https://www.lennar.com/new-homes/texas/houston/katy/anniston/richmond-collection | W26: 2026-09-27
A27: hou-anniston#6 | B27: houston | C27: hou-anniston | D27: Anniston | E27: Lennar | F27: Pinnacle Collection | J27: 335990 | L27: From $335,990 | M27: 443990 | N27: $443,990 | O27: 2423 | P27: 3671 | Q27: 7 | R27: 4 | S27: 4 | T27: 136 | V27: https://www.lennar.com/new-homes/texas/houston/katy/anniston/pinnacle-collection | W27: 2026-09-27
A28: hou-anniston#7 | B28: houston | C28: hou-anniston | D28: Anniston | E28: Lennar | F28: Fairway Collection | J28: 335990 | L28: From $335,990 | M28: 457990 | N28: $457,990 | O28: 2386 | P28: 3308 | Q28: 7 | R28: 5 | S28: 5 | T28: 138 | V28: https://www.lennar.com/new-homes/texas/houston/katy/anniston/fairway-collection | W28: 2026-09-27
A29: hou-anniston#8 | B29: houston | C29: hou-anniston | D29: Anniston | E29: Lennar | F29: Fairway II Collection | J29: 386990 | L29: Coming Soon; plans from $386,990 | M29: 495990 | N29: $495,990 | O29: 2386 | P29: 3308 | Q29: 7 | R29: 0 | S29: 0 | V29: https://www.lennar.com/new-homes/texas/houston/katy/anniston/fairway-ii-collection | W29: 2026-09-27
A30: hou-audubon#1 | B30: houston | C30: hou-audubon | D30: Audubon | E30: Aderra 62+ (age-restricted neighborhood) | F30: Aderra, Heron Run district | G30: 45 | H30: 45 | I30: 1 | J30: 300000 | K30: yes | L30: Homes are priced from the low $300,000s | M30: 387341 | N30: $387,341 (highest listed floor plan) | O30: 1362 | P30: 1740 | Q30: 4 | S30: 0 | V30: https://audubonliving.com/aderra/ | W30: 2026-09-27
A31: hou-audubon#2 | B31: houston | C31: hou-audubon | D31: Audubon | E31: Century Communities | F31: Lonestar Collection | J31: 200000 | K31: yes | L31: From the High $200s | M31: 366900 | N31: $366,900 (Beckenham, 15467 Park Perch Place) | R31: 7 | S31: 4 | T31: 168 | U31: Explore Our Special Financing Offers – Available for a Limited Time! | V31: https://www.centurycommunities.com/find-your-new-home/texas/houston-metro/magnolia/audubon/ | W31: 2026-09-27
A32: hou-audubon#3 | B32: houston | C32: hou-audubon | D32: Audubon | E32: Century Communities | F32: Liberty Collection | J32: 200000 | K32: yes | L32: From the High $200s | M32: 389900 | N32: $389,900 (Sandown, 40523 Slough Way, Oct. move-in) | R32: 9 | S32: 1 | T32: 162 | U32: Explore Our Special Financing Offers – Available for a Limited Time! | V32: https://www.centurycommunities.com/find-your-new-home/texas/houston-metro/magnolia/audubon/ | W32: 2026-09-27
A33: hou-audubon#4 | B33: houston | C33: hou-audubon | D33: Audubon | E33: Chesmar Homes | G33: 55 | H33: 55 | J33: 469990 | L33: Starting From: $469,990 | M33: 547990 | N33: Melody, Starting From $547,990 | O33: 2052 | P33: 3169 | Q33: 11 | S33: 0 | U33: 4.999% (5.737% APR) FHA 30yr, fixed-rate special financing on select homes! | V33: https://www.chesmar.com/texas/houston-new-homes/magnolia/audubon/ | W33: 2026-09-27
A34: hou-audubon#5 | B34: houston | C34: hou-audubon | D34: Audubon | E34: David Weekley Homes | F34: Terrace Collection | G34: 45 | H34: 45 | I34: 1, 2 | J34: 349990 | L34: From: $349,990 (The Flora) | M34: 422990 | N34: From: $422,990 (The Holly) | O34: 1815 | P34: 2814 | Q34: 8 | S34: 0 | U34: NEW EMPLOYEE PRICING EVENT | UP TO $40,000 IN NEW HOME SAVINGS | V34: https://www.davidweekleyhomes.com/new-homes/tx/houston/magnolia/audubon-45-homesites | W34: 2026-09-27
A35: hou-audubon#6 | B35: houston | C35: hou-audubon | D35: Audubon | E35: David Weekley Homes | F35: Ascent Collection | G35: 55 | H35: 55 | I35: 1, 2 | J35: 434990 | L35: From: $434,990 (The Wildflower) | M35: 591846 | N35: $591,846 (The Begonia, 16819 Deep Wingbeat Way) | O35: 2091 | P35: 3495 | Q35: 9 | R35: 10 | S35: 5 | T35: 196 | U35: NEW EMPLOYEE PRICING EVENT | UP TO $40,000 IN NEW HOME SAVINGS | V35: https://www.davidweekleyhomes.com/new-homes/tx/houston/magnolia/audubon-55 | W35: 2026-09-27
A36: hou-audubon#7 | B36: houston | C36: hou-audubon | D36: Audubon | E36: Drees Custom Homes | G36: 80 | H36: 80 | J36: 730000 | K36: yes | L36: From the $730s | M36: 899990 | N36: $899,990 (38265 Heron Nest Way) | O36: 3096 | P36: 5035 | Q36: 10 | R36: 4 | S36: 4 | T36: 229 | V36: https://audubonliving.com/drees-custom-homes/ | W36: 2026-09-27
A37: hou-audubon#8 | B37: houston | C37: hou-audubon | D37: Audubon | E37: Empire Homes | G37: 60 | H37: 60 | J37: 550000 | K37: yes | L37: From the $550s | O37: 2447 | P37: 3828 | S37: 0 | V37: https://audubonliving.com/empire-homes/ | W37: 2026-09-27
A38: hou-audubon#9 | B38: houston | C38: hou-audubon | D38: Audubon | E38: Perry Homes | F38: 45' model | G38: 45 | H38: 45 | J38: 370000 | K38: yes | L38: From the high $300s | O38: 1600 | P38: 2800 | S38: 3 | T38: 206 | V38: https://audubonliving.com/perry-homes/ | W38: 2026-09-27
A39: hou-audubon#10 | B39: houston | C39: hou-audubon | D39: Audubon | E39: Perry Homes | F39: 60' model | G39: 60 | H39: 60 | J39: 470000 | K39: yes | L39: From the high $400s | O39: 2400 | P39: 4100 | S39: 4 | T39: 214 | V39: https://audubonliving.com/perry-homes/ | W39: 2026-09-27
A40: hou-audubon#11 | B40: houston | C40: hou-audubon | D40: Audubon | E40: Perry Homes | F40: 70' model | G40: 70 | H40: 70 | J40: 600000 | K40: yes | L40: From the low $600s | O40: 3200 | P40: 4400 | S40: 0 | V40: https://audubonliving.com/perry-homes/ | W40: 2026-09-27
...

Sheet Communities
A1: community_id | B1: market | C1: community | D1: developer | E1: county | F1: city | G1: zip | H1: school_district | I1: acres | J1: planned_homes | K1: first_homes | L1: rclco_rank | M1: rclco_sales | N1: rclco_year | O1: n_builders | P1: n_product_lines | Q1: lot_widths_ft | R1: from_min | S1: from_median | T1: from_max | U1: qmi_n | V1: qmi_median_price | W1: qmi_median_sqft | X1: qmi_median_ppsf | Y1: zip_zhvi | Z1: zip_zhvi_month | AA1: zip_zhvi_yoy | AB1: zip_zhvi_5y | AC1: zip_redfin_median_sale | AD1: zip_redfin_ppsf | AE1: zip_redfin_sold_90d | AF1: zip_redfin_dom | AG1: zip_redfin_period_end | AH1: lat_zip_centroid | AI1: lon_zip_centroid | AJ1: nearest_cbd | AK1: miles_to_nearest_cbd | AL1: website | AM1: community_price_text
A2: hou-artavia | B2: houston | C2: ARTAVIA | D2: AIRIA Development Company | E2: Montgomery | F2: Conroe | G2: 77302 | H2: Conroe ISD | I2: 2842 | J2: 6500 | O2: 10 | P2: 18 | Q2: 40, 45, 50, 55, 60, 65, 70, 80 | R2: 330991 | S2: 488995 | T2: 850000 | U2: 49 | V2: 517990 | W2: 2948 | X2: 182 | Y2: 326778 | Z2: 2026-08 | AA2: -0.0227 | AB2: 0.0986 | AC2: 335775 | AD2: 153 | AE2: 264 | AF2: 114 | AG2: 2026-05-31 | AH2: 30.20341 | AI2: -95.33118 | AJ2: Houston | AK2: 30.7 | AL2: https://artaviatx.com/
A3: hou-amira | B3: houston | C3: Amira | D3: Johnson Development | E3: Harris | F3: Tomball | G3: 77377 | H3: Tomball ISD | I3: 554 | J3: 1100 | K3: 2019 | O3: 2 | P3: 2 | Q3: 45, 50 | R3: 349067 | S3: 359534 | T3: 370000 | U3: 5 | V3: 418112 | W3: 2562 | X3: 182 | Y3: 396798 | Z3: 2026-08 | AA3: -0.0119 | AB3: 0.1655 | AC3: 380000 | AD3: 164 | AE3: 200 | AF3: 63 | AG3: 2026-05-31 | AH3: 30.0706 | AI3: -95.71555 | AJ3: Houston | AK3: 29.8 | AL3: https://amiratexas.com/ | AM3: New Homes FROM THE LOW $300s
A4: hou-anniston | B4: houston | C4: Anniston | D4: Friendswood Development Company | E4: Harris | F4: Katy | G4: 77493 | H4: Katy ISD | L4: 12 | M4: 775 | O4: 1 | P4: 8 | R4: 219991 | S4: 288990 | T4: 386990 | U4: 34 | V4: 310990 | W4: 2173 | X4: 142 | Y4: 336733 | Z4: 2026-08 | AA4: -0.0396 | AB4: 0.0929 | AC4: 340000 | AD4: 159 | AE4: 735 | AF4: 67 | AG4: 2026-05-31 | AH4: 29.8532 | AI4: -95.8315 | AJ4: Houston | AK4: 28.4 | AL4: https://friendswooddevelopment.com/communities/master-planned/anniston | AM4: Lennar - from the $260s
A5: hou-audubon | B5: houston | C5: Audubon | D5: Audubon Magnolia Development, LLC (managed by Sam Yager Inc.) | E5: Montgomery | F5: Magnolia | G5: 77354 | H5: Magnolia ISD | I5: 3000 | J5: 5000 | O5: 12 | P5: 17 | Q5: 40, 45, 50, 55, 60, 70, 80 | R5: 200000 | S5: 469990 | T5: 749995 | U5: 42 | V5: 568995 | W5: 2742 | X5: 196 | Y5: 378164 | Z5: 2026-08 | AA5: -0.0149 | AB5: 0.1508 | AC5: 338065 | AD5: 164 | AE5: 359 | AF5: 80.5 | AG5: 2026-05-31 | AH5: 30.22054 | AI5: -95.72072 | AJ5: Houston | AK5: 38.1 | AL5: https://audubonliving.com/ | AM5: From the $300s - $1M+
A6: hou-austin-point | B6: houston | C6: Austin Point | D6: The Signorelli Company | E6: Fort Bend | F6: Richmond | G6: 77469 | H6: Lamar CISD | I6: 4700 | J6: 10000 | O6: 9 | P6: 12 | Q6: 35, 40, 45, 50, 60, 70 | R6: 200000 | S6: 385394 | T6: 750000 | U6: 32 | V6: 429995 | W6: 2600 | X6: 163 | Y6: 337586 | Z6: 2026-08 | AA6: -0.0227 | AB6: 0.1256 | AC6: 330440 | AD6: 156 | AE6: 361 | AF6: 55 | AG6: 2026-05-31 | AH6: 29.4914 | AI6: -95.7021 | AJ6: Houston | AK6: 27.3 | AL6: https://www.austinpoint.com/ | AM6: New homes from the $200s to $900s in Fort Bend County.
A7: hou-baytown-crossings | B7: houston | C7: Baytown Crossings | D7: Friendswood Development Company | E7: Harris | F7: Baytown | G7: 77521 | H7: Goose Creek CISD | I7: 520 | J7: 1600 | L7: 35 | M7: 264 | O7: 2 | P7: 11 | Q7: 45, 50, 60 | R7: 193991 | S7: 271990 | T7: 380990 | U7: 16 | V7: 285990 | W7: 1966 | X7: 146 | Y7: 253942 | Z7: 2026-08 | AA7: -0.01 | AB7: 0.1239 | AC7: 257875 | AD7: 134 | AE7: 196 | AF7: 41 | AG7: 2026-05-31 | AH7: 29.8119 | AI7: -94.9633 | AJ7: Houston | AK7: 24.6 | AL7: https://friendswooddevelopment.com/communities/master-planned/baytown-crossings
A8: hou-bluestem | B8: houston | C8: Bluestem | D8: The Signorelli Company | E8: Waller | F8: Brookshire | G8: 77423 | H8: Royal ISD | I8: 356 | J8: 1300 | K8: 2024 | O8: 3 | P8: 4 | R8: 259857 | S8: 259857 | T8: 259857 | U8: 9 | V8: 304990 | W8: 1961 | X8: 155 | Y8: 365601 | Z8: 2026-08 | AA8: -0.0282 | AB8: 0.1051 | AC8: 334990 | AD8: 159 | AE8: 229 | AF8: 76.5 | AG8: 2026-05-31 | AH8: 29.8331 | AI8: -95.9869 | AJ8: Houston | AK8: 37.3 | AL8: https://www.bluestemtx.com/
A9: hou-briarley | B9: houston | C9: Briarley | D9: Johnson Development | E9: Montgomery | F9: Montgomery | G9: 77316 | H9: Montgomery ISD | I9: 388 | O9: 5 | P9: 6 | Q9: 60, 70, 80 | R9: 489990 | S9: 586990 | T9: 670000 | U9: 10 | V9: 655490 | W9: 3587 | X9: 182 | Y9: 413912 | Z9: 2026-08 | AA9: -0.0244 | AB9: 0.1668 | AC9: 374990 | AD9: 162 | AE9: 505 | AF9: 88 | AG9: 2026-05-31 | AH9: 30.3062 | AI9: -95.6864 | AJ9: Houston | AK9: 42.2 | AL9: https://briarleytx.com/ | AM9: New homes from the $500s on spacious 60′-80′ homesites
A10: hou-bridgeland | B10: houston | C10: Bridgeland | D10: Howard Hughes | E10: Harris | F10: Cypress | G10: 77433 | H10: Waller ISD; Cy-Fair ISD | I10: 11500 | L10: 11 | M10: 812 | O10: 17 | P10: 34 | Q10: 40, 45, 50, 55, 60, 65, 70, 80, 90 | R10: 256991 | S10: 429495 | T10: 1200000 | U10: 84 | V10: 537530 | W10: 2634 | X10: 214 | Y10: 424653 | Z10: 2026-08 | AA10: -0.0127 | AB10: 0.1618 | AC10: 427790 | AD10: 175 | AE10: 677 | AF10: 58 | AG10: 2026-05-31 | AH10: 29.94082 | AI10: -95.75261 | AJ10: Houston | AK10: 26.1 | AL10: https://www.bridgeland.com/
